Workbook

Sheet Raw Data
A1: Mel | B1: Age | C1: Number of Months with the Company | D1: Gender | E1: Annual Salary (as declared) | F1: Laptop Manufacturer of Choice | G1: Laptop Operating System of Choice | H1: Phone of Choice
A2: 1 | B2: 66 | C2: 476 | D2: Male | E2: 86000 | F2: MacBook | G2: MacOS | H2: Apple
A3: 2 | B3: 65 | C3: 425 | D3: Male | E3: 61000 | F3: HP | G3: Windows | H3: Apple
A4: 3 | B4: 50 | C4: 387 | D4: Female | E4: 86000 | F4: HP | G4: Windows | H4: Apple
A5: 4 | B5: 50 | C5: 385 | D5: Female | E5: 98000 | F5: Lenovo | G5: Windows | H5: Android
A6: 5 | B6: 50 | C6: 381 | D6: Male | E6: 77000 | F6: Lenovo | G6: Windows | H6: Android
A7: 6 | B7: 46 | C7: 337 | D7: Male | E7: 87500 | F7: Asus | G7: Windows | H7: Android
A8: 7 | B8: 53 | C8: 329 | D8: Male | E8: 51500 | F8: Lenovo | G8: Windows | H8: Android
A9: 8 | B9: 44 | C9: 295 | D9: Male | E9: 83500 | F9: Lenovo | G9: Windows | H9: Android
A10: 9 | B10: 42 | C10: 280 | D10: Male | E10: 62000 | F10: Lenovo | G10: Linux | H10: No Preference
A11: 10 | B11: 40 | C11: 275 | D11: Male | E11: 81000 | F11: MacBook | G11: MacOS | H11: Apple
A12: 11 | B12: 51 | C12: 269 | D12: Male | E12: 63000 | F12: Dell | G12: Windows | H12: Apple
A13: 12 | B13: 51 | C13: 261 | D13: Male | E13: 35000 | F13: Asus | G13: Windows | H13: Android
... A122: 121 | B122: 20 | C122: 21 | D122: Male | E122: 22000 | F122: HP | G122: Windows | H122: No Preference
A123: 122 | B123: 23 | C123: 21 | D123: Male | E123: 42500 | F123: Chromebook | G123: Chrome OS | H123: No Preference | V123: Peugeot 2008
A124: 123 | B124: 62 | C124: 20 | D124: Female | E124: 24500 | F124: MacBook | G124: MacOS | H124: Apple
A125: 124 | B125: 20 | C125: 19 | D125: Male | E125: 29000 | F125: Lenovo | G125: Windows | H125: Apple
A126: 125 | B126: 20 | C126: 19 | D126: Female | E126: 33000 | F126: MacBook | G126: MacOS | H126: Apple
A127: 126 | B127: 26 | C127: 18 | D127: Male | E127: 70500 | F127: MacBook | G127: MacOS | H127: No Preference
A128: 127 | B128: 29 | C128: 17 | D128: Male | E128: 24000 | F128: MacBook | G128: MacOS | H128: Apple
A129: 128 | B129: 41 | C129: 17 | D129: Male | E129: 29500 | F129: MacBook | G129: MacOS | H129: Apple
A130: 129 | B130: 25 | C130: 17 | D130: Male | E130: 47500 | F130: MacBook | G130: MacOS | H130: Apple
A131: 130 | B131: 23 | C131: 15 | D131: Female | E131: 23500 | F131: Dell | G131: Windows | H131: Apple
A132: 131 | B132: 21 | C132: 15 | D132: Female | E132: 24000 | F132: Lenovo | G132: Linux | H132: Apple
A133: 132 | B133: 34 | C133: 15 | D133: Female | E133: 44500 | F133: MacBook | G133: MacOS | H133: Apple
A134: 133 | B134: 43 | C134: 15 | D134: Male | E134: 92000 | F134: MacBook | G134: MacOS | H134: No Preference
A135: 134 | B135: 30 | C135: 15 | D135: Male | E135: 99000 | F135: MacBook | G135: MacOS | H135: Apple
... A185: 184 | B185: 31 | C185: 1 | D185: Male | E185: 92000 | F185: Lenovo | G185: Windows | H185: Android

Sheet Primary Research Data
A4: ID | B4: When choosing a computer which of these features is the most important to you? | C4: On a phone what features are most important to you? | D4: Which of these operating systems would you rather use? | E4: Which mobile operating system do you prefer? | F4: Which of the following ports do you use (please select all that apply) | G4: Computer Rating | H4: Phone Rating | I4: Please describe the features/functionality of your phone you most appreciate | J4: Please describe the features/functionality of your Laptop/Desktop you most appreciate | K4: Please list any peripheral devices you use in your day-to-day activities
A5: 1 | B5: Price;Performance;Style;Build quality;Pre-installed software;The form factor (size, shape, weight);Ease of future upgrade;Portability ; | C5: Battery Life;Camera quality (Photo);The phone's performance (specs);Camera quality {Video};Support for wireless charging; | D5: Windows;Linux;Chrome OS;Mac OS; | E5: Apple | F5: HDMI;USB-C;Headphone jack;Display Port; | G5: 7 | H5: 9 | I5: I appreciate the security features my phone has and how it is quite stable | J5: The performance as i do a lot of programming being able to do multiple things at once is quite important for me | K5: Keyboard, mouse, printer, webcam and computer monitor
A6: 2 | B6: Build quality;Pre-installed software;The form factor (size, shape, weight);Portability ;Price;Performance;Style;Ease of future upgrade; | C6: Battery Life;The phone's performance (specs);Camera quality (Photo);Camera quality {Video};Support for wireless charging; | D6: Linux;Windows;Chrome OS;Mac OS; | E6: No Preference | F6: USB-C;USB-A;HDMI;Headphone jack;Display Port; | G6: 5 | H6: 9 | I6: Camera quality | J6: How long I’ve had it, so it’s long life capabilities | K6: I use a wide range of different devices such as Keyboard, mouse, microphone and typically a 2nd monitor
A7: 3 | B7: Performance;Ease of future upgrade;Price;Style;Build quality;Pre-installed software;The form factor (size, shape, weight);Portability ; | C7: The phone's performance (specs);Battery Life;Camera quality (Photo);Camera quality {Video};Support for wireless charging; | D7: Windows;Mac OS;Linux;Chrome OS; | E7: Apple | F7: USB-C;USB-A;HDMI; | G7: 10 | H7: 9 | I7: Camera, battery life | J7: Performance | K7: Mouse, speakers
A8: 4 | B8: Performance;Build quality;Portability ;The form factor (size, shape, weight);Ease of future upgrade;Pre-installed software;Price;Style; | C8: Battery Life;The phone's performance (specs);Support for wireless charging;Camera quality (Photo);Camera quality {Video}; | D8: Windows;Linux;Chrome OS;Mac OS; | E8: Android | F8: USB-C;USB-A;HDMI;Headphone jack;Display Port; | G8: 7 | H8: 1 | I8: I hate the entire thing. My work phone is a very old I-phone that is out of date, difficult to use and took an age to set up. There is genuinely nothing I like about it. | J8: Good battery life, reasonable performance, easily connects to things. | K8: Jabra speaker, multiple monitors (32inch), Thinkpad hub, wireless keyboard and mouse, webcam
A9: 5 | B9: Price;Performance;Build quality;The form factor (size, shape, weight);Portability ;Style;Ease of future upgrade;Pre-installed software; | D9: Windows;Mac OS;Chrome OS;Linux; | E9: Android | F9: USB-C;USB-A;HDMI;VGA;Display Port; | G9: 6 | H9: 8 | I9: Decent battery life, great camera, very fluid, quick and intuitive to use with its OS gestures and features. All for a very reasonable price | J9: Reasonably speedy, quite robust, 360 movement with touch | K9: Headphones, optical mouse, keyboard
A10: 6 | B10: Performance;Price;Build quality;The form factor (size, shape, weight);Portability ;Ease of future upgrade;Style;Pre-installed software; | C10: The phone's performance (specs);Battery Life;Camera quality (Photo);Support for wireless charging;Camera quality {Video}; | E10: Android | F10: USB-C;USB-A;Headphone jack;HDMI; | G10: 8 | H10: 5 | I10: Simplicity, ease of use. | J10: Reliable, compatible with external devices such as keyboard. Handles multitasking relatively well. | K10: Wireless keyboard and mouse, wired headset.
A11: 7 | B11: Price;Performance;Build quality;The form factor (size, shape, weight);Portability ;Style;Ease of future upgrade;Pre-installed software; | C11: The phone's performance (specs);Battery Life;Camera quality (Photo);Camera quality {Video};Support for wireless charging; | E11: Apple | F11: USB-C;USB-A;HDMI;VGA;Display Port; | G11: 8 | H11: 9 | I11: OLED screen and high refresh rate. Makes screen tear less during animations | J11: Portability due to being on my feet alot Size so its easier to carry Battery life is good as im away from a charger quite alot | K11: Keyboard, mouse, headset, webcam
A12: 8 | B12: Price;Performance;Build quality;Ease of future upgrade;Pre-installed software;Portability ;The form factor (size, shape, weight);Style; | C12: Camera quality (Photo);Camera quality {Video};Battery Life;The phone's performance (specs);Support for wireless charging; | E12: No Preference | F12: USB-C;HDMI;USB-A; | G12: 7 | H12: 8 | I12: Camera quality and battery life | J12: Work laptop: Ability to run several applications at once. Example: code editor, web browser and Microsoft Teams. Allows me to carry out my day to day work with ease. | K12: Smart watch
A13: 9 | E13: Android | F13: USB-C;USB-A;HDMI;Headphone jack; | G13: 9 | H13: 7 | I13: I enjoy the layout of the phone at the general performance and battery life of the phone during the first year of owning it. | J13: I appreciate how much load tolerance my PC can handle, whether that is with lots of internet tabs open, or a resource heavy video game, it seems to handle itself well with little problem | K13: Mouse, Keyboard, Controller, Earphones, Headset
A14: 10 | E14: Android | F14: HDMI; | G14: 8 | H14: 9 | I14: storage | J14: storage | K14: card reader
A15: 11 | B15: Price;Performance;Ease of future upgrade;Build quality;The form factor (size, shape, weight);Portability ;Style;Pre-installed software; | D15: Linux;Windows;Mac OS;Chrome OS; | E15: Apple | F15: USB-C;USB-A;HDMI;VGA;Headphone jack;Display Port; | G15: 8 | H15: 8 | I15: It takes photos of network ports adequately, and a good for MFA text messages! | J15: Needs to run multiple heavy duty apps simultaneously, be small and quiet, and reliable. | K15: Mouse, Keyboard, Camera, Video Capture, KVM, Oscilloscope, Signal Generator, Multimeter, Headphones, Speakers.
A16: 12 | E16: Android | F16: USB-C;USB-A;HDMI;VGA;Headphone jack;Display Port; | G16: 7 | H16: 5 | I16: it is waterproof | J16: speed, its fast | K16: Audio interface, Studio monitors, keyboard, mouse
A17: 13 | C17: The phone's performance (specs);Battery Life;Camera quality (Photo);Camera quality {Video};Support for wireless charging; | D17: Windows;Mac OS;Chrome OS;Linux; | E17: Android | F17: USB-C;USB-A;HDMI; | G17: 7 | H17: 8 | I17: Camera, Ram and storage. | J17: Cpu, Ram and graphics card | K17: laptops, ipads and phones
A18: 14 | B18: Performance;Build quality;Price;The form factor (size, shape, weight);Pre-installed software;Ease of future upgrade;Style;Portability ; | C18: Battery Life;The phone's performance (specs);Camera quality (Photo);Camera quality {Video};Support for wireless charging; | D18: Windows;Linux;Chrome OS;Mac OS; | E18: Android | F18: HDMI;Headphone jack;Display Port;USB-A; | G18: 6 | H18: 8 | I18: Long battery life. Navigation bar making applications easy to navigate between. Messaging services. | J18: Keyboard. Notification center and management. | K18: Speakers. Headphones. USB mouse.
A19: 15 | B19: Price;The form factor (size, shape, weight);Performance;Build quality;Ease of future upgrade;Style;Portability ;Pre-installed software; | C19: Battery Life;Support for wireless charging;The phone's performance (specs);Camera quality (Photo);Camera quality {Video}; | D19: Linux;Windows;Mac OS;Chrome OS; | E19: No Preference | F19: USB-C;USB-A;HDMI;Display Port;Headphone jack; | G19: 9 | H19: 6 | I19: Camera, NFC. | J19: 32 GB of RAM, responsive. | K19: Wireless mouse and keyboard, Security Key, Headset, Monitor/Display.
A20: 16 | B20: Price;Performance;Ease of future upgrade;Build quality;Portability ;Style;The form factor (size, shape, weight);Pre-installed software; | C20: Battery Life;The phone's performance (specs);Camera quality (Photo);Camera quality {Video};Support for wireless charging; | D20: Windows;Chrome OS;Mac OS;Linux; | E20: Apple | F20: USB-C;USB-A;HDMI;Display Port; | G20: 10 | H20: 6 | I20: I appreciate how fast and easy to use the phone is. | J20: The performance of my desktop is the feature I most appreciate as well as the build quality | K20: Headphones, Keyboard, mouse, monitor, webcam, microphone, controller
A21: 17 | B21: Build quality;Performance;Price;The form factor (size, shape, weight);Portability ;Ease of future upgrade;Pre-installed software;Style; | C21: Battery Life;The phone's performance (specs);Support for wireless charging;Camera quality (Photo);Camera quality {Video}; | D21: Linux;Windows;Mac OS;Chrome OS; | E21: Android | F21: USB-C;Headphone jack;USB-A; | G21: 9 | H21: 10 | I21: 7 day battery, wireless charging | J21: Solid, capable of heavy number crunching | K21: various docks/ port externders, usb-serial,
A22: 18 | B22: Build quality;Performance;Price;The form factor (size, shape, weight);Portability ;Ease of future upgrade;Style;Pre-installed software; | C22: The phone's performance (specs);Battery Life;Support for wireless charging;Camera quality (Photo);Camera quality {Video}; | E22: Apple | F22: USB-C;USB-A;Display Port; | G22: 10 | H22: 9 | I22: For work the Teams app & Outlook. | J22: The display, performance and ease of use. | K22: Keyboard, Monitor, Headphones, Mouse.
A23: 19 | E23: No Preference | F23: USB-C;USB-A;HDMI;Headphone jack; | G23: 8 | H23: 6 | I23: screen size, speed | J23: Battery life and RAM for multitasking | K23: keyboard, mouse
A24: 20 | B24: Price;Performance;Build quality;The form factor (size, shape, weight);Portability ;Style;Ease of future upgrade;Pre-installed software; | C24: The phone's performance (specs);Battery Life;Camera quality (Photo);Camera quality {Video};Support for wireless charging; | D24: Windows;Mac OS;Linux;Chrome OS; | E24: No Preference | F24: USB-A;USB-C; | G24: 5 | H24: 5 | I24: 1. Camera Quality High-resolution cameras with advanced features like night mode, portrait mode, and optical zoom are highly appreciated for capturing stunning photos and videos. 2. Battery Life Long-lasting battery life is crucial for staying connected throughout the day without constantly needing to recharge. 3. User Interface A smooth and intuitive user interface enhances the overall user experience, making it easy to navigate and use various apps and features. 4. Performance Fast processors and ample RAM ensure that the phone runs smoothly, even when multitasking or using resource-intensive apps. 5. Connectivity Features like 5G support, Wi-Fi 6, and Bluetooth 5.0 provide faster and more reliable connections for internet browsing, streaming, and connecting to other devices. 6. Security Biometric authentication methods like fingerprint sensors and facial recognition add an extra layer of security and convenience. | J24: 1. Performance High-speed processors, ample RAM, and solid-state drives (SSDs) ensure fast and efficient performance, even when multitasking or running demanding applications. 2. Display Quality High-resolution displays with accurate color reproduction and good brightness levels enhance the visual experience, whether for work, gaming, or media consumption. 3. Battery Life For laptops, long battery life is crucial for working on the go without constantly needing to recharge. 4. Portability Lightweight and slim designs make laptops easy to carry around, which is especially important for those who travel frequently. 5. Connectivity Options Multiple ports (USB, HDMI, Thunderbolt, etc.) and wireless connectivity options (Wi-Fi, Bluetooth) provide flexibility for connecting various peripherals and devices. | K24: Keyboard, Mouse, Monitor,Printer, Headphones, Microphone
A25: 21 | B25: Price;Build quality;Performance;The form factor (size, shape, weight);Portability ;Ease of future upgrade;Style;Pre-installed software; | C25: Battery Life;The phone's performance (specs);Support for wireless charging;Camera quality (Photo);Camera quality {Video}; | E25: Apple | F25: USB-C;USB-A;HDMI;VGA;Headphone jack;Display Port; | G25: 8 | H25: 8 | I25: long software support, dual sim, wi-fi calling | J25: multi-display, backlit keyboard | K25: FIDO2 security token
A26: 22 | B26: Performance;Build quality;The form factor (size, shape, weight);Price;Style;Ease of future upgrade;Portability ;Pre-installed software; | C26: Battery Life;Camera quality (Photo);The phone's performance (specs);Camera quality {Video};Support for wireless charging; | D26: Windows;Mac OS;Chrome OS;Linux; | E26: Apple | F26: USB-C;USB-A;HDMI;VGA;Headphone jack;Display Port; | G26: 10 | H26: 10 | I26: Compatibility with other devices Ease of use Battery life Photo quality | J26: Touch screen Small and light Attractive design Sensible price | K26: Printer Screen Keyboard Mouse
A27: 23 | B27: Performance;Price;Build quality;Pre-installed software;Ease of future upgrade;Portability ;The form factor (size, shape, weight);Style; | C27: The phone's performance (specs);Camera quality (Photo);Battery Life;Camera quality {Video};Support for wireless charging; | D27: Windows;Chrome OS;Mac OS;Linux; | E27: Apple | F27: USB-A;USB-C;HDMI;VGA;Headphone jack;Display Port; | G27: 8 | H27: 6 | I27: The range of things it can provide with ease of use! | J27: My laptop enables me to use it for work items as well as for the gaming aspects. It came with pre installed software to play games without much issue. | K27: Trackball mouse, 60% keyboard and Xbox Controller.
A28: 24 | B28: Performance;Price;Portability ;Build quality;The form factor (size, shape, weight);Ease of future upgrade;Pre-installed software;Style; | C28: Camera quality (Photo);Camera quality {Video};Battery Life;The phone's performance (specs);Support for wireless charging; | D28: Windows;Chrome OS;Mac OS;Linux; | E28: Android | F28: USB-C;HDMI;Headphone jack;Display Port; | G28: 10 | H28: 10 | I28: photo quality very good | J28: lightweight and portable | K28: headphones, kindle,
A29: 25 | B29: Price;Build quality;The form factor (size, shape, weight);Performance;Portability ;Ease of future upgrade;Style;Pre-installed software; | C29: Battery Life;The phone's performance (specs);Camera quality (Photo);Camera quality {Video};Support for wireless charging; | D29: Windows;Linux;Chrome OS;Mac OS; | E29: Android | F29: USB-C;USB-A;HDMI;Headphone jack;Display Port; | G29: 2 | H29: 3 | I29: Long battery life. | J29: Clear & bright screen. Long battery life | K29: tracker ball. headphones
A30: 26 | B30: Performance;Build quality;Price;Ease of future upgrade;The form factor (size, shape, weight);Style;Portability ;Pre-installed software; | C30: The phone's performance (specs);Battery Life;Support for wireless charging;Camera quality (Photo);Camera quality {Video}; | D30: Mac OS;Windows;Linux;Chrome OS; | E30: Apple | F30: USB-C;HDMI;USB-A;VGA;Headphone jack;Display Port; | G30: 6 | H30: 7 | I30: Apple Work flow is ideal for me. Ease of use | J30: Clear display | K30: Printer, mouse, keyboard, speakers, 2nd display
A31: 27 | B31: Price;Performance;Ease of future upgrade;The form factor (size, shape, weight);Build quality;Pre-installed software;Style;Portability ; | C31: The phone's performance (specs);Camera quality (Photo);Camera quality {Video};Battery Life;Support for wireless charging; | D31: Windows;Chrome OS;Mac OS;Linux; | F31: USB-C;HDMI;Display Port;USB-A;VGA;Headphone jack; | G31: 10 | H31: 10 | I31: Value for money, good battery life. Camera works well in low light | J31: I can carry out multiple tasks without it slowing down. More than enough storage. | K31: Multi-card reader, visualiser, speakers
A32: 28 | B32: Performance;Build quality;Ease of future upgrade;The form factor (size, shape, weight);Portability ;Style;Price;Pre-installed software; | C32: Battery Life;The phone's performance (specs);Support for wireless charging;Camera quality (Photo);Camera quality {Video}; | D32: Windows;Chrome OS;Mac OS;Linux; | E32: Android | F32: USB-C;USB-A; | G32: 3 | H32: 7 | I32: Can check pupils work and message them, can check email | J32: Google Classroom functions | K32: Phone Tablet PC
A33: 29 | B33: Performance;Price;Build quality;Portability ;The form factor (size, shape, weight);Ease of future upgrade;Style;Pre-installed software; | C33: The phone's performance (specs);Battery Life;Camera quality (Photo);Camera quality {Video};Support for wireless charging; | D33: Mac OS;Windows;Chrome OS;Linux; | E33: Apple | F33: USB-C;HDMI;Headphone jack;Display Port;USB-A; | G33: 7 | H33: 9
A34: 30 | B34: Performance;Build quality;Ease of future upgrade;The form factor (size, shape, weight);Price;Portability ;Pre-installed software;Style; | C34: The phone's performance (specs);Battery Life;Support for wireless charging;Camera quality (Photo);Camera quality {Video}; | D34: Windows;Chrome OS;Linux;Mac OS; | E34: Android | F34: USB-C;USB-A;HDMI; | G34: 9 | H34: 5 | I34: Internet, Google maps, email and SMS | J34: Internet, multimedia | K34: Classroom display board
A35: 31 | B35: Performance;Build quality;Ease of future upgrade;Price;Style;The form factor (size, shape, weight);Pre-installed software;Portability ; | C35: Camera quality (Photo);Camera quality {Video};The phone's performance (specs);Battery Life;Support for wireless charging; | D35: Windows;Linux;Mac OS;Chrome OS; | E35: Apple | F35: USB-C;USB-A;HDMI;VGA;Headphone jack;Display Port; | G35: 4 | H35: 8 | I35: Quality phones/video, cloud storage, build quality, style | J35: multi screens, SSD's, running volume | K35: Monitors, keyboard, mouse, mic, webcam, speakers, printer
A36: 32 | B36: Performance;Price;Pre-installed software;Build quality;The form factor (size, shape, weight);Ease of future upgrade;Style;Portability ; | C36: The phone's performance (specs);Battery Life;Camera quality (Photo);Camera quality {Video};Support for wireless charging; | D36: Windows;Mac OS;Chrome OS;Linux; | E36: Apple | F36: USB-A;HDMI;USB-C;Headphone jack; | G36: 8 | H36: 9 | I36: Good battery life. Good camera/video. Quick and responsive | J36: memory. screen display. | K36: NA
A37: 33 | B37: Performance;Price;Ease of future upgrade;Portability ;Build quality;Style;Pre-installed software;The form factor (size, shape, weight); | C37: Battery Life;Camera quality (Photo);Camera quality {Video};The phone's performance (specs);Support for wireless charging; | D37: Windows;Linux;Chrome OS;Mac OS; | E37: Apple | F37: USB-C;USB-A;Headphone jack;HDMI; | G37: 4 | H37: 9 | I37: Performance | J37: Battery life | K37: Speakers, dual monitor, mouse, keyboard
A38: 34 | B38: Performance;Build quality;Portability ;The form factor (size, shape, weight);Style;Price;Pre-installed software;Ease of future upgrade; | C38: The phone's performance (specs);Battery Life;Support for wireless charging;Camera quality (Photo);Camera quality {Video}; | D38: Windows;Mac OS;Chrome OS;Linux; | E38: Apple | F38: USB-C;USB-A;HDMI;Headphone jack;Display Port; | G38: 8 | H38: 8 | I38: Ease of app availability and downloads, versatility and compatibility with my other Apple products | J38: Portability, access to main work apps and collaborative tools (MS Office suite, Teams, Co-pilot), minimal downtime required for updates | K38: Headphones, mouse
A39: 35 | B39: Performance;Price;Pre-installed software;Ease of future upgrade;Build quality;The form factor (size, shape, weight);Portability ;Style; | C39: Battery Life;Camera quality (Photo);Camera quality {Video};The phone's performance (specs);Support for wireless charging; | D39: Chrome OS;Mac OS;Windows;Linux; | E39: Apple | F39: USB-C;USB-A;HDMI; | G39: 8 | H39: 8 | I39: Cloud storage and compatibility with other devices. | J39: Cloud storage, compatibility with other devices and portability. | K39: Wireless printer, Bluetooth earbuds/headphones.
A40: 36 | B40: Portability ;Performance;Build quality;The form factor (size, shape, weight);Price;Ease of future upgrade;Pre-installed software;Style; | C40: Battery Life;Camera quality (Photo);Camera quality {Video};The phone's performance (specs);Support for wireless charging; | D40: Windows;Chrome OS;Mac OS;Linux; | E40: Android | F40: USB-C;USB-A;HDMI; | G40: 5 | H40: 6 | I40: Camera, storage, speed | J40: Old device, very slow, need an upgrade | K40: Chrome cast for tv
A41: 37 | B41: Performance;Build quality;Ease of future upgrade;Price;The form factor (size, shape, weight);Portability ;Style;Pre-installed software; | C41: Battery Life;The phone's performance (specs);Camera quality (Photo);Camera quality {Video};Support for wireless charging; | D41: Windows;Mac OS;Chrome OS;Linux; | E41: Apple | F41: USB-C;USB-A;HDMI;VGA;Headphone jack; | G41: 10 | H41: 10 | I41: Reasonably compact ind interfaces nicely with my IPad/TV(With Fire stick) | J41: As above | K41: Fire stick, Apple TV, Apple Watch, AirTag.
A42: 38 | B42: Price;Performance;Pre-installed software;Ease of future upgrade;The form factor (size, shape, weight);Build quality;Portability ;Style; | C42: Battery Life;Support for wireless charging;The phone's performance (specs);Camera quality (Photo);Camera quality {Video}; | D42: Windows;Chrome OS;Mac OS;Linux; | E42: Apple | F42: Display Port; | G42: 8 | H42: 8 | I42: Battery life | K42: Ear pods
A43: 39 | B43: Performance;Price;The form factor (size, shape, weight);Portability ;Build quality;Ease of future upgrade;Style;Pre-installed software; | C43: Camera quality (Photo);Camera quality {Video};Battery Life;The phone's performance (specs);Support for wireless charging; | D43: Mac OS;Windows;Linux;Chrome OS; | E43: No Preference | F43: USB-C;USB-A;Headphone jack;HDMI; | G43: 10 | H43: 6 | I43: Cheap so I'm not worried about damaging it, long battery life and still functioning well after 7 years | J43: Performance, portability | K43: Keyboard & mouse when working from home, ipad as second screen or writing tablet
...

Sheet Task 1
D2: Phone of Choice Total (Raw Data)
C3: Apple | D3: =COUNTIF('Raw Data'!H2:H185, "Apple") -> 82
C4: Android | D4: =COUNTIF('Raw Data'!H2:H185, "Android") -> 85
C5: No Preference | D5: =COUNTIF('Raw Data'!H2:H185, "No Preference") -> 17
D25: Phone of Choice Total (Primary Research Data)
C26: Apple | D26: =COUNTIF('Primary Research Data'!E5:E45, "Apple") -> 20
C27: Android | D27: =COUNTIF('Primary Research Data'!E5:E45, "Android") -> 14
C28: No Preference | D28: =COUNTIF('Primary Research Data'!E5:E45, "No Preference") -> 6
C29: Missing Data | D29: =COUNTIF('Primary Research Data'!E5:E45, "") -> 1
C31: Comment on two pie charts | D31: The Primary Research Data has a smaller sample size, and therefore may be less accurate. Some data was missing in the Primary Research Data, which was caused by a respondant not answering this question, so this data could not be accounted for. The percentage of Android users is slightly lower in the Primary Research Data(down to 34% compared to the Raw Data's 46%), with Apple being preferred in the Primary Research Data. The No Preference option is also more popular in the Primary Research Data, being at 15% compared to the Raw Data's 9%.
C33: Number | D33: Employees of Each Gender (Raw Data)
C34: Male | D34: =COUNTIF('Raw Data'!D2:D185, "Male") -> 132
C35: Female | D35: =COUNTIF('Raw Data'!D2:D185, "Female") -> 51
C36: Non-binary | D36: =COUNTIF('Raw Data'!D2:D185, "Non-binary") -> 1
C58: Total Employees (Raw Data) | D58: =COUNT('Raw Data'!A2:A185) -> 184
C59: Employees Under 30 | D59: =COUNTIF('Raw Data'!B2:B185, "<=30") -> 91
C60: Percentage of Employees Under 30 | D60: =((D59/D58)*100) -> 49.456522

Sheet Task 2
C2: Laptop Manufacturer of Choice
C3: Chrome OS | D3: Linux | E3: MacOS | F3: Windows | G3: Total
A4: Laptop Operating System of Choice | B4: Acer | C4: =COUNTIFS('Raw Data'!$F$2:$F$185, "Acer", 'Raw Data'!$G$2:$G$185, "Chrome OS") -> 0 | D4: =COUNTIFS('Raw Data'!$F$2:$F$185, "Acer", 'Raw Data'!$G$2:$G$185, "Linux") -> 0 | E4: =COUNTIFS('Raw Data'!$F$2:$F$185, "Acer", 'Raw Data'!$G$2:$G$185, "MacOS") -> 0 | F4: =COUNTIFS('Raw Data'!$F$2:$F$185, "Acer", 'Raw Data'!$G$2:$G$185, "Windows") -> 2 | G4: =SUM($C$4:$F$4) -> 2
B5: Asus | C5: =COUNTIFS('Raw Data'!$F$2:$F$185, "Asus", 'Raw Data'!$G$2:$G$185, "Chrome OS") -> 0 | D5: =COUNTIFS('Raw Data'!$F$2:$F$185, "Asus", 'Raw Data'!$G$2:$G$185, "Linux") -> 0 | E5: =COUNTIFS('Raw Data'!$F$2:$F$185, "Asus", 'Raw Data'!$G$2:$G$185, "MacOS") -> 0 | F5: =COUNTIFS('Raw Data'!$F$2:$F$185, "Asus", 'Raw Data'!$G$2:$G$185, "Windows") -> 22 | G5: =SUM($C$5:$F$5) -> 22
B6: Chromebook | C6: =COUNTIFS('Raw Data'!$F$2:$F$185, "Chromebook", 'Raw Data'!$G$2:$G$185, "Chrome OS") -> 6 | D6: =COUNTIFS('Raw Data'!$F$2:$F$185, "Chromebook", 'Raw Data'!$G$2:$G$185, "Linux") -> 0 | E6: =COUNTIFS('Raw Data'!$F$2:$F$185, "Chromebook", 'Raw Data'!$G$2:$G$185, "MacOS") -> 0 | F6: =COUNTIFS('Raw Data'!$F$2:$F$185, "Chromebook", 'Raw Data'!$G$2:$G$185, "Windows") -> 0 | G6: =SUM($C$6:$F$6) -> 6
B7: Dell | C7: =COUNTIFS('Raw Data'!$F$2:$F$185, "Dell", 'Raw Data'!$G$2:$G$185, "Chrome OS") -> 0 | D7: =COUNTIFS('Raw Data'!$F$2:$F$185, "Dell", 'Raw Data'!$G$2:$G$185, "Linux") -> 6 | E7: =COUNTIFS('Raw Data'!$F$2:$F$185, "Dell", 'Raw Data'!$G$2:$G$185, "MacOS") -> 0 | F7: =COUNTIFS('Raw Data'!$F$2:$F$185, "Dell", 'Raw Data'!$G$2:$G$185, "Windows") -> 16 | G7: =SUM($C$7:$F$7) -> 22
B8: HP | C8: =COUNTIFS('Raw Data'!$F$2:$F$185, "HP", 'Raw Data'!$G$2:$G$185, "Chrome OS") -> 0 | D8: =COUNTIFS('Raw Data'!$F$2:$F$185, "HP", 'Raw Data'!$G$2:$G$185, "Linux") -> 0 | E8: =COUNTIFS('Raw Data'!$F$2:$F$185, "HP", 'Raw Data'!$G$2:$G$185, "MacOS") -> 0 | F8: =COUNTIFS('Raw Data'!$F$2:$F$185, "HP", 'Raw Data'!$G$2:$G$185, "Windows") -> 16 | G8: =SUM($C$8:$F$8) -> 16
B9: Lenovo | C9: =COUNTIFS('Raw Data'!$F$2:$F$185, "Lenovo", 'Raw Data'!$G$2:$G$185, "Chrome OS") -> 0 | D9: =COUNTIFS('Raw Data'!$F$2:$F$185, "Lenovo", 'Raw Data'!$G$2:$G$185, "Linux") -> 13 | E9: =COUNTIFS('Raw Data'!$F$2:$F$185, "Lenovo", 'Raw Data'!$G$2:$G$185, "MacOS") -> 0 | F9: =COUNTIFS('Raw Data'!$F$2:$F$185, "Lenovo", 'Raw Data'!$G$2:$G$185, "Windows") -> 43 | G9: =SUM($C$9:$F$9) -> 56
B10: MacBook | C10: =COUNTIFS('Raw Data'!$F$2:$F$185, "MacBook", 'Raw Data'!$G$2:$G$185, "Chrome OS") -> 0 | D10: =COUNTIFS('Raw Data'!$F$2:$F$185, "MacBook", 'Raw Data'!$G$2:$G$185, "Linux") -> 0 | E10: =COUNTIFS('Raw Data'!$F$2:$F$185, "MacBook", 'Raw Data'!$G$2:$G$185, "MacOS") -> 59 | F10: =COUNTIFS('Raw Data'!$F$2:$F$185, "MacBook", 'Raw Data'!$G$2:$G$185, "Windows") -> 0 | G10: =SUM($C$10:$F$10) -> 59
B11: Samsung | C11: =COUNTIFS('Raw Data'!$F$2:$F$185, "Samsung", 'Raw Data'!$G$2:$G$185, "Chrome OS") -> 0 | D11: =COUNTIFS('Raw Data'!$F$2:$F$185, "Samsung", 'Raw Data'!$G$2:$G$185, "Linux") -> 0 | E11: =COUNTIFS('Raw Data'!$F$2:$F$185, "Samsung", 'Raw Data'!$G$2:$G$185, "MacOS") -> 0 | F11: =COUNTIFS('Raw Data'!$F$2:$F$185, "Samsung", 'Raw Data'!$G$2:$G$185, "Windows") -> 1 | G11: =SUM($C$11:$F$11) -> 1
B12: Total | C12: =SUM($C$4:$C$11) -> 6 | D12: =SUM($D$4:$D$11) -> 19 | E12: =SUM($E$4:$E$11) -> 59 | F12: =SUM($F$4:$F$11) -> 100 | G12: =SUM($G$4:$G$11) -> 184
B14: Percentage of employee wanting Mac OS | C14: =($E$12/$G$12*100) -> 32.065217
B15: Percentage of employee wanting an HP laptop with Windows | C15: =($F$8/$G$12*100) -> 8.6956522
B16: Percentage of employee wanting Windows, given they chose a Lenovo Laptop | C16: =($F$9/$G$9*100) -> 76.785714
B17: Percentage of employee wanting a Dell laptop, given they chose a Linux OS | C17: =($D$7/D12*100) -> 31.578947

Sheet Task 3
B4: Smallest Annual Salary in Raw Data | C4: =MIN('Raw Data'!$E$2:E$185) -> 20000
B5: Largest Annual Salary in Raw Data | C5: =MAX('Raw Data'!$E$2:$E$185) -> 99000
B7: Row Labels | C7: Count of Employees with that Annual Salary
B8: 20000-29999 | C8: 59
B9: 30000-39999 | C9: 33
B10: 40000-49999 | C10: 22
B11: 50000-59999 | C11: 10
B12: 60000-69999 | C12: 20
B13: 70000-79999 | C13: 17
B14: 80000-89999 | C14: 12
B15: 90000-99999 | C15: 11
B16: Grand Total | C16: 184
B26: Comment | C26: From this histogram, you can draw the conclusion that annual salaries are not normally distributed. There is a clear weighting towards the lower end of the annual salary range. Therefore, you would need to use the median, rather than the mean to calculate a fair average of annual salary for all employees. There also appears to be a 'salary ceiling' around the £50000-£59999 range, where the amount of employees in the previous three ranges keeps decreasing in frequency up to this range, and then the amount of employees in the range afterwards (£60000-£69999) increases before again continuing to decrease in frequency in ranges afterwards. This could suggest there are two 'groupings' of job roles either side of the £50000-£59999 range, but this would require using data outside the annual salaries to draw any conclusions.

Sheet Task 4
B4: Maximum number of months with the company | C4: =MAX('Raw Data'!$C$2:$C$185) -> 476
B5: Minimum number of months with the company | C5: =MIN('Raw Data'!$C$2:$C$185) -> 1
B6: Range | C6: =($C$4-$C$5) -> 475
B7: Interval Width | C7: =$C$6/10 -> 47.5
B8: Bin Width | C8: =ROUND($C$7, 0) -> 48
B10: Bin | C10: Midpoint | D10: Midpoint2 | E10: Frequency | F10: Sum of frequencies | G10: Frequency x Midpoint | H10: Sum of Frequency X Midpoint | I10: Frequency x Midpoint2 | J10: Sum of Frequncy x Midpoint2
B11: 0-48 | C11: 24.5 | D11: =C11^2 -> 600.25 | E11: =COUNTIFS('Raw Data'!$C$2:$C$185, ">=0", 'Raw Data'!$C$2:$C$185, "<=48") -> 102 | F11: =SUM($E$11:$E$20) -> 184 | G11: =C11*E11 -> 2499 | H11: =SUM($G$11:$G$20) -> 14972 | I11: =D11 * E11 -> 61225.5 | J11: =SUM($I$11:$I$20) -> 2724430
B12: 49-96 | C12: 72.5 | D12: =C12^2 -> 5256.25 | E12: =COUNTIFS('Raw Data'!$C$2:$C$185, ">=49", 'Raw Data'!$C$2:$C$185, "<=96") -> 34 | G12: =C12*E12 -> 2465 | I12: =D12 * E12 -> 178712.5
B13: 97-144 | C13: 120.5 | D13: =C13^2 -> 14520.25 | E13: =COUNTIFS('Raw Data'!$C$2:$C$185, ">=97", 'Raw Data'!$C$2:$C$185, "<=144") -> 15 | G13: =C13*E13 -> 1807.5 | I13: =D13 * E13 -> 217803.75
B14: 145-192 | C14: 168.5 | D14: =C14^2 -> 28392.25 | E14: =COUNTIFS('Raw Data'!$C$2:$C$185, ">=145", 'Raw Data'!$C$2:$C$185, "<=192") -> 10 | G14: =C14*E14 -> 1685 | I14: =D14 * E14 -> 283922.5
B15: 193-240 | C15: 216.5 | D15: =C15^2 -> 46872.25 | E15: =COUNTIFS('Raw Data'!$C$2:$C$185, ">=193", 'Raw Data'!$C$2:$C$185, "<=240") -> 10 | G15: =C15*E15 -> 2165 | I15: =D15 * E15 -> 468722.5
B16: 241-288 | C16: 264.5 | D16: =C16^2 -> 69960.25 | E16: =COUNTIFS('Raw Data'!$C$2:$C$185, ">=241", 'Raw Data'!$C$2:$C$185, "<=288") -> 5 | G16: =C16*E16 -> 1322.5 | I16: =D16 * E16 -> 349801.25
B17: 289-336 | C17: 312.5 | D17: =C17^2 -> 97656.25 | E17: =COUNTIFS('Raw Data'!$C$2:$C$185, ">=289", 'Raw Data'!$C$2:$C$185, "<=336") -> 2 | G17: =C17*E17 -> 625 | I17: =D17 * E17 -> 195312.5
B18: 337-384 | C18: 360.5 | D18: =C18^2 -> 129960.25 | E18: =COUNTIFS('Raw Data'!$C$2:$C$185, ">=337", 'Raw Data'!$C$2:$C$185, "<=384") -> 2 | G18: =C18*E18 -> 721 | I18: =D18 * E18 -> 259920.5
B19: 385-432 | C19: 408.5 | D19: =C19^2 -> 166872.25 | E19: =COUNTIFS('Raw Data'!$C$2:$C$185, ">=385", 'Raw Data'!$C$2:$C$185, "<=432") -> 3 | G19: =C19*E19 -> 1225.5 | I19: =D19 * E19 -> 500616.75
B20: 433-480 | C20: 456.5 | D20: =C20^2 -> 208392.25 | E20: =COUNTIFS('Raw Data'!$C$2:$C$185, ">=433", 'Raw Data'!$C$2:$C$185, "<=480") -> 1 | G20: =C20*E20 -> 456.5 | I20: =D20 * E20 -> 208392.25
B22: Comment | H22: Mean without inbuilt function | I22: Variance without inbuilt function | J22: Standard Deviation without inbuilt function
B23: The mean is much closer to the minimum than the maximum, indicating that few people stay for long at the company, but those that do tend to last. The standard deviation is also higher than the mean, indicating there is a lot of deviation. | H23: =H11/F11 -> 81.369565 | I23: =$J$11/$F$11-$H$23^2 -> 8185.6786 | J23: =SQRT($I$23) -> 90.47474
B27: Mean with inbuilt function | C27: Standard Deviation with inbuilt function | D27: Comment
B28: =AVERAGE('Raw Data'!$C$2:$C$185) -> 76.934783 | C28: =_xlfn.STDEV.P('Raw Data'!$C$2:$C$185) -> 92.617294 | D28: The difference between the values that were calculated and those using the inbuilt function is due to the midpoints being used, whereas the inbuilt functions are using the actual values
B31: Mean with inbuilt function for computer rating (Primary Research Data) | C31: Standard Deviation for computer rating (Primary Research Data) | D31: Comment
B32: =AVERAGE('Primary Research Data'!G5:G45) -> 7.4390244 | C32: =_xlfn.STDEV.P('Primary Research Data'!G5:G45) -> 2.0127494 | D32: The mean for the computer rating is much closer to the maximum possible rating than the mean for the employees number of months with the company, meaning employees that stay tend to stay a long time, but few do, wieghting the mean towards the minimum. The mean in the primary research data mens that the majority are actually happy with their computers. The standard deviation is roughly the same ratio of the range for both data sets, indicating the deviation for the mean is similar.
